Workbook

Sheet Actual Results
A1: Round of 64 | B1: Round of 32 | C1: Sweet 16 | D1: Elite 8 | E1: Final 4 | F1: Championship | G1: Winner
A2: (1) Duke | B2: (1) Duke | C2: (1) Duke | I2: Correct Pick Value | J2: 10 | K2: 20 | L2: 40 | M2: 80 | N2: 160 | O2: 320
A3: (16) Siena | I3: Contestant | J3: Round of 64 | K3: Round of 32 | L3: Sweet 16 | M3: Elite 8 | N3: Final 4 | O3: Championship | P3: Total Points
A4: (8) Ohio St | I4: Shawn | J4: {=(SUMPRODUCT(--(B2:B65<>""), --(B2:B65=Shawn!B2:B65)) * J2)} -> 260 | K4: {=(SUMPRODUCT(--(C2:C65<>""), --(C2:C65=Shawn!C2:C65)) * K2)} -> 180 | L4: {=(SUMPRODUCT(--(D2:D65<>""), --(D2:D65=Shawn!D2:D65)) * L2)} -> 0 | M4: {=(SUMPRODUCT(--(E2:E65<>""), --(E2:E65=Shawn!E2:E65)) * M2)} -> 0 | N4: {=(SUMPRODUCT(--(F2:F65<>""), --(F2:F65=Shawn!F2:F65)) * N2)} -> 0 | O4: {=(SUMPRODUCT(--(G2:G65<>""), --(G2:G65=Shawn!G2:G65)) * O2)} -> 0 | P4: =SUM(J4:O4) -> 440
A5: (9) TCU | B5: (9) TCU | I5: Henny | J5: {=(SUMPRODUCT(--(B2:B65<>""), --(B2:B65=Henny!B2:B65)) * J2)} -> 240 | K5: {=(SUMPRODUCT(--(C2:C65<>""), --(C2:C65=Henny!C2:C65)) * K2)} -> 220 | L5: {=(SUMPRODUCT(--(D2:D65<>""), --(D2:D65=Henny!D2:D65)) * L2)} -> 0 | M5: {=(SUMPRODUCT(--(E2:E65<>""), --(E2:E65=Henny!E2:E65)) * M2)} -> 0 | N5: {=(SUMPRODUCT(--(F2:F65<>""), --(F2:F65=Henny!F2:F65)) * N2)} -> 0 | O5: {=(SUMPRODUCT(--(G2:G65<>""), --(G2:G65=Henny!G2:G65)) * O2)} -> 0 | P5: =SUM(J5:O5) -> 460
A6: (5) St. John's | B6: (5) St. John's | C6: (5) St. John's | I6: Lucia | J6: {=(SUMPRODUCT(--(B2:B65<>""), --(B2:B65=Lucia!B2:B65)) * J2)} -> 240 | K6: {=(SUMPRODUCT(--(C2:C65<>""), --(C2:C65=Lucia!C2:C65)) * K2)} -> 160 | L6: {=(SUMPRODUCT(--(D2:D65<>""), --(D2:D65=Lucia!D2:D65)) * L2)} -> 0 | M6: {=(SUMPRODUCT(--(E2:E65<>""), --(E2:E65=Lucia!E2:E65)) * M2)} -> 0 | N6: {=(SUMPRODUCT(--(F2:F65<>""), --(F2:F65=Lucia!F2:F65)) * N2)} -> 0 | O6: {=(SUMPRODUCT(--(G2:G65<>""), --(G2:G65=Lucia!G2:G65)) * O2)} -> 0 | P6: =SUM(J6:O6) -> 400
A7: (12) N. Iowa | I7: Mary | J7: {=(SUMPRODUCT(--(B2:B65<>""), --(B2:B65=Mary!B2:B65)) * J2)} -> 250 | K7: {=(SUMPRODUCT(--(C2:C65<>""), --(C2:C65=Mary!C2:C65)) * K2)} -> 180 | L7: {=(SUMPRODUCT(--(D2:D65<>""), --(D2:D65=Mary!D2:D65)) * L2)} -> 0 | M7: {=(SUMPRODUCT(--(E2:E65<>""), --(E2:E65=Mary!E2:E65)) * M2)} -> 0 | N7: {=(SUMPRODUCT(--(F2:F65<>""), --(F2:F65=Mary!F2:F65)) * N2)} -> 0 | O7: {=(SUMPRODUCT(--(G2:G65<>""), --(G2:G65=Mary!G2:G65)) * O2)} -> 0 | P7: =SUM(J7:O7) -> 430
A8: (4) Kansas | B8: (4) Kansas | I8: Chad | J8: {=(SUMPRODUCT(--(B2:B65<>""), --(B2:B65=Chad!B2:B65)) * J2)} -> 260 | K8: {=(SUMPRODUCT(--(C2:C65<>""), --(C2:C65=Chad!C2:C65)) * K2)} -> 220 | L8: {=(SUMPRODUCT(--(D2:D65<>""), --(D2:D65=Chad!D2:D65)) * L2)} -> 0 | M8: {=(SUMPRODUCT(--(E2:E65<>""), --(E2:E65=Chad!E2:E65)) * M2)} -> 0 | N8: {=(SUMPRODUCT(--(F2:F65<>""), --(F2:F65=Chad!F2:F65)) * N2)} -> 0 | O8: {=(SUMPRODUCT(--(G2:G65<>""), --(G2:G65=Chad!G2:G65)) * O2)} -> 0 | P8: =SUM(J8:O8) -> 480
A9: (13) Cal Baptist | I9: Truett | J9: {=(SUMPRODUCT(--(B2:B65<>""), --(B2:B65=Truett!B2:B65)) * J2)} -> 280 | K9: {=(SUMPRODUCT(--(C2:C65<>""), --(C2:C65=Truett!C2:C65)) * K2)} -> 240 | L9: {=(SUMPRODUCT(--(D2:D65<>""), --(D2:D65=Truett!D2:D65)) * L2)} -> 0 | M9: {=(SUMPRODUCT(--(E2:E65<>""), --(E2:E65=Truett!E2:E65)) * M2)} -> 0 | N9: {=(SUMPRODUCT(--(F2:F65<>""), --(F2:F65=Truett!F2:F65)) * N2)} -> 0 | O9: {=(SUMPRODUCT(--(G2:G65<>""), --(G2:G65=Truett!G2:G65)) * O2)} -> 0 | P9: =SUM(J9:O9) -> 520
A10: (6) Louisville | B10: (6) Louisville | I10: Sabine | J10: {=(SUMPRODUCT(--(B2:B65<>""), --(B2:B65=Sabine!B2:B65)) * J2)} -> 210 | K10: {=(SUMPRODUCT(--(C2:C65<>""), --(C2:C65=Sabine!C2:C65)) * K2)} -> 160 | L10: {=(SUMPRODUCT(--(D2:D65<>""), --(D2:D65=Sabine!D2:D65)) * L2)} -> 0 | M10: {=(SUMPRODUCT(--(E2:E65<>""), --(E2:E65=Sabine!E2:E65)) * M2)} -> 0 | N10: {=(SUMPRODUCT(--(F2:F65<>""), --(F2:F65=Sabine!F2:F65)) * N2)} -> 0 | O10: {=(SUMPRODUCT(--(G2:G65<>""), --(G2:G65=Sabine!G2:G65)) * O2)} -> 0 | P10: =SUM(J10:O10) -> 370
A11: (11) South Florida | I11: Tim | J11: {=(SUMPRODUCT(--(B2:B65<>""), --(B2:B65=Tim!B2:B65)) * J2)} -> 270 | K11: {=(SUMPRODUCT(--(C2:C65<>""), --(C2:C65=Tim!C2:C65)) * K2)} -> 220 | L11: {=(SUMPRODUCT(--(D2:D65<>""), --(D2:D65=Tim!D2:D65)) * L2)} -> 0 | M11: {=(SUMPRODUCT(--(E2:E65<>""), --(E2:E65=Tim!E2:E65)) * M2)} -> 0 | N11: {=(SUMPRODUCT(--(F2:F65<>""), --(F2:F65=Tim!F2:F65)) * N2)} -> 0 | O11: {=(SUMPRODUCT(--(G2:G65<>""), --(G2:G65=Tim!G2:G65)) * O2)} -> 0 | P11: =SUM(J11:O11) -> 490
A12: (3) Michigan St | B12: (3) Michigan St | C12: (3) Michigan St | I12: Colombina | J12: {=(SUMPRODUCT(--(B2:B65<>""), --(B2:B65=Colombina!B2:B65)) * J2)} -> 260 | K12: {=(SUMPRODUCT(--(C2:C65<>""), --(C2:C65=Colombina!C2:C65)) * K2)} -> 180 | L12: {=(SUMPRODUCT(--(D2:D65<>""), --(D2:D65=Colombina!D2:D65)) * L2)} -> 0 | M12: {=(SUMPRODUCT(--(E2:E65<>""), --(E2:E65=Colombina!E2:E65)) * M2)} -> 0 | N12: {=(SUMPRODUCT(--(F2:F65<>""), --(F2:F65=Colombina!F2:F65)) * N2)} -> 0 | O12: {=(SUMPRODUCT(--(G2:G65<>""), --(G2:G65=Colombina!G2:G65)) * O2)} -> 0 | P12: =SUM(J12:O12) -> 440
A13: (14) N. Dakota St | I13: Cynthia | J13: {=(SUMPRODUCT(--(B2:B65<>""), --(B2:B65=Cynthia!B2:B65)) * J2)} -> 260 | K13: {=(SUMPRODUCT(--(C2:C65<>""), --(C2:C65=Cynthia!C2:C65)) * K2)} -> 200 | L13: {=(SUMPRODUCT(--(D2:D65<>""), --(D2:D65=Cynthia!D2:D65)) * L2)} -> 0 | M13: {=(SUMPRODUCT(--(E2:E65<>""), --(E2:E65=Cynthia!E2:E65)) * M2)} -> 0 | N13: {=(SUMPRODUCT(--(F2:F65<>""), --(F2:F65=Cynthia!F2:F65)) * N2)} -> 0 | O13: {=(SUMPRODUCT(--(G2:G65<>""), --(G2:G65=Cynthia!G2:G65)) * O2)} -> 0 | P13: =SUM(J13:O13) -> 460
A14: (7) UCLA | B14: (7) UCLA | I14: Chalamet | J14: {=(SUMPRODUCT(--(B2:B65<>""), --(B2:B65=Chalamet!B2:B65)) * J2)} -> 240 | K14: {=(SUMPRODUCT(--(C2:C65<>""), --(C2:C65=Chalamet!C2:C65)) * K2)} -> 40 | L14: {=(SUMPRODUCT(--(D2:D65<>""), --(D2:D65=Chalamet!D2:D65)) * L2)} -> 0 | M14: {=(SUMPRODUCT(--(E2:E65<>""), --(E2:E65=Chalamet!E2:E65)) * M2)} -> 0 | N14: {=(SUMPRODUCT(--(F2:F65<>""), --(F2:F65=Chalamet!F2:F65)) * N2)} -> 0 | O14: {=(SUMPRODUCT(--(G2:G65<>""), --(G2:G65=Chalamet!G2:G65)) * O2)} -> 0 | P14: =SUM(J14:O14) -> 280
A15: (10) UCF | I15: Eli | J15: {=(SUMPRODUCT(--(B2:B65<>""), --(B2:B65=Eli!B2:B65)) * J2)} -> 270 | K15: {=(SUMPRODUCT(--(C2:C65<>""), --(C2:C65=Eli!C2:C65)) * K2)} -> 220 | L15: {=(SUMPRODUCT(--(D2:D65<>""), --(D2:D65=Eli!D2:D65)) * L2)} -> 0 | M15: {=(SUMPRODUCT(--(E2:E65<>""), --(E2:E65=Eli!E2:E65)) * M2)} -> 0 | N15: {=(SUMPRODUCT(--(F2:F65<>""), --(F2:F65=Eli!F2:F65)) * N2)} -> 0 | O15: {=(SUMPRODUCT(--(G2:G65<>""), --(G2:G65=Eli!G2:G65)) * O2)} -> 0 | P15: =SUM(J15:O15) -> 490
A16: (2) UConn | B16: (2) UConn | C16: (2) UConn | I16: Emma | J16: {=(SUMPRODUCT(--(B2:B65<>""), --(B2:B65=Emma!B2:B65)) * J2)} -> 280 | K16: {=(SUMPRODUCT(--(C2:C65<>""), --(C2:C65=Emma!C2:C65)) * K2)} -> 180 | L16: {=(SUMPRODUCT(--(D2:D65<>""), --(D2:D65=Emma!D2:D65)) * L2)} -> 0 | M16: {=(SUMPRODUCT(--(E2:E65<>""), --(E2:E65=Emma!E2:E65)) * M2)} -> 0 | N16: {=(SUMPRODUCT(--(F2:F65<>""), --(F2:F65=Emma!F2:F65)) * N2)} -> 0 | O16: {=(SUMPRODUCT(--(G2:G65<>""), --(G2:G65=Emma!G2:G65)) * O2)} -> 0 | P16: =SUM(J16:O16) -> 460
A17: (15) Furman | I17: Arden | J17: {=(SUMPRODUCT(--(B2:B65<>""), --(B2:B65=Arden!B2:B65)) * J2)} -> 240 | K17: {=(SUMPRODUCT(--(C2:C65<>""), --(C2:C65=Arden!C2:C65)) * K2)} -> 240 | L17: {=(SUMPRODUCT(--(D2:D65<>""), --(D2:D65=Arden!D2:D65)) * L2)} -> 0 | M17: {=(SUMPRODUCT(--(E2:E65<>""), --(E2:E65=Arden!E2:E65)) * M2)} -> 0 | N17: {=(SUMPRODUCT(--(F2:F65<>""), --(F2:F65=Arden!F2:F65)) * N2)} -> 0 | O17: {=(SUMPRODUCT(--(G2:G65<>""), --(G2:G65=Arden!G2:G65)) * O2)} -> 0 | P17: =SUM(J17:O17) -> 480
A18: (1) Florida | B18: (1) Florida | I18: Maren | J18: {=(SUMPRODUCT(--(B2:B65<>""), --(B2:B65=Maren!B2:B65)) * J2)} -> 250 | K18: {=(SUMPRODUCT(--(C2:C65<>""), --(C2:C65=Maren!C2:C65)) * K2)} -> 220 | L18: {=(SUMPRODUCT(--(D2:D65<>""), --(D2:D65=Maren!D2:D65)) * L2)} -> 0 | M18: {=(SUMPRODUCT(--(E2:E65<>""), --(E2:E65=Maren!E2:E65)) * M2)} -> 0 | N18: {=(SUMPRODUCT(--(F2:F65<>""), --(F2:F65=Maren!F2:F65)) * N2)} -> 0 | O18: {=(SUMPRODUCT(--(G2:G65<>""), --(G2:G65=Maren!G2:G65)) * O2)} -> 0 | P18: =SUM(J18:O18) -> 470
A19: **(16) PVAM/LEH | I19: Pete | J19: {=(SUMPRODUCT(--(B2:B65<>""), --(B2:B65=Pete!B2:B65)) * J2)} -> 250 | K19: {=(SUMPRODUCT(--(C2:C65<>""), --(C2:C65=Pete!C2:C65)) * K2)} -> 140 | L19: {=(SUMPRODUCT(--(D2:D65<>""), --(D2:D65=Pete!D2:D65)) * L2)} -> 0 | M19: {=(SUMPRODUCT(--(E2:E65<>""), --(E2:E65=Pete!E2:E65)) * M2)} -> 0 | N19: {=(SUMPRODUCT(--(F2:F65<>""), --(F2:F65=Pete!F2:F65)) * N2)} -> 0 | O19: {=(SUMPRODUCT(--(G2:G65<>""), --(G2:G65=Pete!G2:G65)) * O2)} -> 0 | P19: =SUM(J19:O19) -> 390
A20: (8) Clemson | I20: Roman | J20: {=(SUMPRODUCT(--(B2:B65<>""), --(B2:B65=Roman!B2:B65)) * J2)} -> 260 | K20: {=(SUMPRODUCT(--(C2:C65<>""), --(C2:C65=Roman!C2:C65)) * K2)} -> 220 | L20: {=(SUMPRODUCT(--(D2:D65<>""), --(D2:D65=Roman!D2:D65)) * L2)} -> 0 | M20: {=(SUMPRODUCT(--(E2:E65<>""), --(E2:E65=Roman!E2:E65)) * M2)} -> 0 | N20: {=(SUMPRODUCT(--(F2:F65<>""), --(F2:F65=Roman!F2:F65)) * N2)} -> 0 | O20: {=(SUMPRODUCT(--(G2:G65<>""), --(G2:G65=Roman!G2:G65)) * O2)} -> 0 | P20: =SUM(J20:O20) -> 480
A21: (9) Iowa | B21: (9) Iowa | C21: (9) Iowa | I21: Sarah | J21: {=(SUMPRODUCT(--(B2:B65<>""), --(B2:B65=Sarah!B2:B65)) * J2)} -> 250 | K21: {=(SUMPRODUCT(--(C2:C65<>""), --(C2:C65=Sarah!C2:C65)) * K2)} -> 220 | L21: {=(SUMPRODUCT(--(D2:D65<>""), --(D2:D65=Sarah!D2:D65)) * L2)} -> 0 | M21: {=(SUMPRODUCT(--(E2:E65<>""), --(E2:E65=Sarah!E2:E65)) * M2)} -> 0 | N21: {=(SUMPRODUCT(--(F2:F65<>""), --(F2:F65=Sarah!F2:F65)) * N2)} -> 0 | O21: {=(SUMPRODUCT(--(G2:G65<>""), --(G2:G65=Sarah!G2:G65)) * O2)} -> 0 | P21: =SUM(J21:O21) -> 470
A22: (5) Vanderbilt | B22: (5) Vanderbilt | I22: Elaine | J22: {=(SUMPRODUCT(--(B2:B65<>""), --(B2:B65=Elaine!B2:B65)) * J2)} -> 250 | K22: {=(SUMPRODUCT(--(C2:C65<>""), --(C2:C65=Elaine!C2:C65)) * K2)} -> 220 | L22: {=(SUMPRODUCT(--(D2:D65<>""), --(D2:D65=Elaine!D2:D65)) * L2)} -> 0 | M22: {=(SUMPRODUCT(--(E2:E65<>""), --(E2:E65=Elaine!E2:E65)) * M2)} -> 0 | N22: {=(SUMPRODUCT(--(F2:F65<>""), --(F2:F65=Elaine!F2:F65)) * N2)} -> 0 | O22: {=(SUMPRODUCT(--(G2:G65<>""), --(G2:G65=Elaine!G2:G65)) * O2)} -> 0 | P22: =SUM(J22:O22) -> 470
A23: (12) McNeese | I23: August | J23: {=(SUMPRODUCT(--(B2:B65<>""), --(B2:B65=August!B2:B65)) * J2)} -> 280 | K23: {=(SUMPRODUCT(--(C2:C65<>""), --(C2:C65=August!C2:C65)) * K2)} -> 180 | L23: {=(SUMPRODUCT(--(D2:D65<>""), --(D2:D65=August!D2:D65)) * L2)} -> 0 | M23: {=(SUMPRODUCT(--(E2:E65<>""), --(E2:E65=August!E2:E65)) * M2)} -> 0 | N23: {=(SUMPRODUCT(--(F2:F65<>""), --(F2:F65=August!F2:F65)) * N2)} -> 0 | O23: {=(SUMPRODUCT(--(G2:G65<>""), --(G2:G65=August!G2:G65)) * O2)} -> 0 | P23: =SUM(J23:O23) -> 460
A24: (4) Nebraska | B24: (4) Nebraska | C24: (4) Nebraska | I24: Indie | J24: {=(SUMPRODUCT(--(B2:B65<>""), --(B2:B65=Indie!B2:B65)) * J2)} -> 250 | K24: {=(SUMPRODUCT(--(C2:C65<>""), --(C2:C65=Indie!C2:C65)) * K2)} -> 180 | L24: {=(SUMPRODUCT(--(D2:D65<>""), --(D2:D65=Indie!D2:D65)) * L2)} -> 0 | M24: {=(SUMPRODUCT(--(E2:E65<>""), --(E2:E65=Indie!E2:E65)) * M2)} -> 0 | N24: {=(SUMPRODUCT(--(F2:F65<>""), --(F2:F65=Indie!F2:F65)) * N2)} -> 0 | O24: {=(SUMPRODUCT(--(G2:G65<>""), --(G2:G65=Indie!G2:G65)) * O2)} -> 0 | P24: =SUM(J24:O24) -> 430
A25: (13) Troy | I25: Pia | J25: {=(SUMPRODUCT(--(B2:B65<>""), --(B2:B65=Pia!B2:B65)) * J2)} -> 190 | K25: {=(SUMPRODUCT(--(C2:C65<>""), --(C2:C65=Pia!C2:C65)) * K2)} -> 100 | L25: {=(SUMPRODUCT(--(D2:D65<>""), --(D2:D65=Pia!D2:D65)) * L2)} -> 0 | M25: {=(SUMPRODUCT(--(E2:E65<>""), --(E2:E65=Pia!E2:E65)) * M2)} -> 0 | N25: {=(SUMPRODUCT(--(F2:F65<>""), --(F2:F65=Pia!F2:F65)) * N2)} -> 0 | O25: {=(SUMPRODUCT(--(G2:G65<>""), --(G2:G65=Pia!G2:G65)) * O2)} -> 0 | P25: =SUM(J25:O25) -> 290
A26: (6) N. Carolina | I26: Penny | J26: {=(SUMPRODUCT(--(B2:B65<>""), --(B2:B65=Penny!B2:B65)) * J2)} -> 240 | K26: {=(SUMPRODUCT(--(C2:C65<>""), --(C2:C65=Penny!C2:C65)) * K2)} -> 240 | L26: {=(SUMPRODUCT(--(D2:D65<>""), --(D2:D65=Penny!D2:D65)) * L2)} -> 0 | M26: {=(SUMPRODUCT(--(E2:E65<>""), --(E2:E65=Penny!E2:E65)) * M2)} -> 0 | N26: {=(SUMPRODUCT(--(F2:F65<>""), --(F2:F65=Penny!F2:F65)) * N2)} -> 0 | O26: {=(SUMPRODUCT(--(G2:G65<>""), --(G2:G65=Penny!G2:G65)) * O2)} -> 0 | P26: =SUM(J26:O26) -> 480
A27: (11) VCU | B27: (11) VCU | I27: Don | J27: {=(SUMPRODUCT(--(B$2:B$65<>""), --(B$2:B$65=Don!B$2:B$65)) * J$2)} -> 250 | K27: {=(SUMPRODUCT(--(C$2:C$65<>""), --(C$2:C$65=Don!C$2:C$65)) * K$2)} -> 240 | L27: {=(SUMPRODUCT(--(D$2:D$65<>""), --(D$2:D$65=Don!D$2:D$65)) * L$2)} -> 0 | M27: {=(SUMPRODUCT(--(E$2:E$65<>""), --(E$2:E$65=Don!E$2:E$65)) * M$2)} -> 0 | N27: {=(SUMPRODUCT(--(F$2:F$65<>""), --(F$2:F$65=Don!F$2:F$65)) * N$2)} -> 0 | O27: {=(SUMPRODUCT(--(G$2:G$65<>""), --(G$2:G$65=Don!G$2:G$65)) * O$2)} -> 0 | P27: =SUM(J27:O27) -> 490
A28: (3) Illinois | B28: (3) Illinois | C28: (3) Illinois | I28: WInter | J28: {=(SUMPRODUCT(--(B$2:B$65<>""), --(B$2:B$65=Winter!B$2:B$65)) * J$2)} -> 240 | K28: {=(SUMPRODUCT(--(C$2:C$65<>""), --(C$2:C$65=Winter!C$2:C$65)) * K$2)} -> 120 | L28: {=(SUMPRODUCT(--(D$2:D$65<>""), --(D$2:D$65=Winter!D$2:D$65)) * L$2)} -> 0 | M28: {=(SUMPRODUCT(--(E$2:E$65<>""), --(E$2:E$65=Winter!E$2:E$65)) * M$2)} -> 0 | N28: {=(SUMPRODUCT(--(F$2:F$65<>""), --(F$2:F$65=Winter!F$2:F$65)) * N$2)} -> 0 | O28: {=(SUMPRODUCT(--(G$2:G$65<>""), --(G$2:G$65=Winter!G$2:G$65)) * O$2)} -> 0 | P28: =SUM(J28:O28) -> 360
A29: (14) Penn
A30: (7) Saint Mary's
A31: (10) Texas A&M | B31: (10) Texas A&M
A32: (2) Houston | B32: (2) Houston | C32: (2) Houston
A33: (15) Idaho
A34: (1) Arizona | B34: (1) Arizona | C34: (1) Arizona
A35: (16) LIU
A36: (8) Villanova
A37: (9) Utah St | B37: (9) Utah St
A38: (5) Wisconsin
A39: (12) High Point | B39: (12) High Point
A40: (4) Arkansas | B40: (4) Arkansas | C40: (4) Arkansas
...

Sheet Shawn
A1: Round of 64 | B1: Round of 32 | C1: Sweet 16 | D1: Elite 8 | E1: Final 4 | F1: Championship | G1: Winner
A2: (1) Duke | B2: (1) Duke | C2: (1) Duke | D2: (1) Duke | E2: (1) Duke | F2: (1) Duke
A3: (16) Siena
A4: (8) Ohio St
A5: (9) TCU | B5: (9) TCU
A6: (5) St. John's | B6: (5) St. John's
A7: (12) N. Iowa
A8: (4) Kansas | B8: (4) Kansas | C8: (4) Kansas
A9: (13) Cal Baptist
A10: (6) Louisville | B10: (6) Louisville
A11: (11) South Florida
A12: (3) Michigan St | B12: (3) Michigan St | C12: (3) Michigan St | D12: (3) Michigan St
A13: (14) N. Dakota St
A14: (7) UCLA
A15: (10) UCF | B15: (10) UCF
A16: (2) UConn | B16: (2) UConn | C16: (2) UConn
A17: (15) Furman
A18: (1) Florida | B18: (1) Florida | C18: (1) Florida | D18: (1) Florida
A19: **(16) PVAM/LEH
A20: (8) Clemson
A21: (9) Iowa | B21: (9) Iowa
A22: (5) Vanderbilt | B22: (5) Vanderbilt | C22: (5) Vanderbilt
A23: (12) McNeese
A24: (4) Nebraska | B24: (4) Nebraska
A25: (13) Troy
A26: (6) N. Carolina | B26: (6) N. Carolina | C26: (6) N. Carolina
A27: (11) VCU
A28: (3) Illinois | B28: (3) Illinois
A29: (14) Penn
A30: (7) Saint Mary's
A31: (10) Texas A&M | B31: (10) Texas A&M
A32: (2) Houston | B32: (2) Houston | C32: (2) Houston | D32: (2) Houston | E32: (2) Houston
A33: (15) Idaho
A34: (1) Arizona | B34: (1) Arizona | C34: (1) Arizona | D34: (1) Arizona
A35: (16) LIU
A36: (8) Villanova | B36: (8) Villanova
A37: (9) Utah St
A38: (5) Wisconsin | B38: (5) Wisconsin | C38: (5) Wisconsin
A39: (12) High Point
A40: (4) Arkansas | B40: (4) Arkansas
...

Sheet Maren
A1: Round of 64 | B1: Round of 32 | C1: Sweet 16 | D1: Elite 8 | E1: Final 4 | F1: Championship | G1: Winner
A2: (1) Duke | B2: (1) Duke | C2: (1) Duke | D2: (1) Duke
A3: (16) Siena
A4: (8) Ohio St
A5: (9) TCU | B5: (9) TCU
A6: (5) St. John's | B6: (5) St. John's
A7: (12) N. Iowa
A8: (4) Kansas | B8: (4) Kansas | C8: (4) Kansas
A9: (13) Cal Baptist
A10: (6) Louisville | B10: (6) Louisville
A11: (11) South Florida
A12: (3) Michigan St | B12: (3) Michigan St | C12: (3) Michigan St
A13: (14) N. Dakota St
A14: (7) UCLA | B14: (7) UCLA
A15: (10) UCF
A16: (2) UConn | B16: (2) UConn | C16: (2) UConn | D16: (2) UConn | E16: (2) UConn | F16: (2) UConn | G16: (2) UConn
A17: (15) Furman
A18: (1) Florida | B18: (1) Florida | C18: (1) Florida | D18: (1) Florida
A19: **(16) PVAM/LEH
A20: (8) Clemson | B20: (8) Clemson
A21: (9) Iowa
A22: (5) Vanderbilt | B22: (5) Vanderbilt
A23: (12) McNeese
A24: (4) Nebraska | B24: (4) Nebraska | C24: (4) Nebraska
A25: (13) Troy
A26: (6) N. Carolina | B26: (6) N. Carolina | C26: (6) N. Carolina
A27: (11) VCU
A28: (3) Illinois | B28: (3) Illinois
A29: (14) Penn
A30: (7) Saint Mary's | B30: (7) Saint Mary's
A31: (10) Texas A&M
A32: (2) Houston | B32: (2) Houston | C32: (2) Houston | D32: (2) Houston | E32: (2) Houston
A33: (15) Idaho
A34: (1) Arizona | B34: (1) Arizona | C34: (1) Arizona | D34: (1) Arizona | E34: (1) Arizona
A35: (16) LIU
A36: (8) Villanova | B36: (8) Villanova
A37: (9) Utah St
A38: (5) Wisconsin | B38: (5) Wisconsin
A39: (12) High Point
A40: (4) Arkansas | B40: (4) Arkansas | C40: (4) Arkansas
...

Sheet Elaine
A1: Round of 64 | B1: Round of 32 | C1: Sweet 16 | D1: Elite 8 | E1: Final 4 | F1: Championship | G1: Winner
A2: (1) Duke | B2: (1) Duke | C2: (1) Duke | D2: (1) Duke | E2: (1) Duke | F2: (1) Duke | G2: (1) Duke
A3: (16) Siena
A4: (8) Ohio St | B4: (8) Ohio St
A5: (9) TCU
A6: (5) St. John's | B6: (5) St. John's | C6: (5) St. John's
A7: (12) N. Iowa
A8: (4) Kansas | B8: (4) Kansas
A9: (13) Cal Baptist
A10: (6) Louisville
A11: (11) South Florida | B11: (11) South Florida
A12: (3) Michigan St | B12: (3) Michigan St | C12: (3) Michigan St | D12: (3) Michigan St
A13: (14) N. Dakota St
A14: (7) UCLA
A15: (10) UCF | B15: (10) UCF
A16: (2) UConn | B16: (2) UConn | C16: (2) UConn
A17: (15) Furman
A18: (1) Florida | B18: (1) Florida | C18: (1) Florida | D18: (1) Florida
A19: **(16) PVAM/LEH
A20: (8) Clemson
A21: (9) Iowa | B21: (9) Iowa
A22: (5) Vanderbilt | B22: (5) Vanderbilt | C22: (5) Vanderbilt
A23: (12) McNeese
A24: (4) Nebraska
A25: (13) Troy | B25: (13) Troy
A26: (6) N. Carolina
A27: (11) VCU | B27: (11) VCU
A28: (3) Illinois | B28: (3) Illinois | C28: (3) Illinois
A29: (14) Penn
A30: (7) Saint Mary's
A31: (10) Texas A&M | B31: (10) Texas A&M
A32: (2) Houston | B32: (2) Houston | C32: (2) Houston | D32: (2) Houston | E32: (2) Houston
A33: (15) Idaho
A34: (1) Arizona | B34: (1) Arizona | C34: (1) Arizona | D34: (1) Arizona | E34: (1) Arizona | F34: (1) Arizona
A35: (16) LIU
A36: (8) Villanova
A37: (9) Utah St | B37: (9) Utah St
A38: (5) Wisconsin | B38: (5) Wisconsin | C38: (5) Wisconsin
A39: (12) High Point
A40: (4) Arkansas | B40: (4) Arkansas
...

Sheet Colombina
A1: Round of 64 | B1: Round of 32 | C1: Sweet 16 | D1: Elite 8 | E1: Final 4 | F1: Championship | G1: Winner
A2: (1) Duke | B2: (1) Duke | C2: (1) Duke
A3: (16) Siena
A4: (8) Ohio St | B4: (8) Ohio St
A5: (9) TCU
A6: (5) St. John's | B6: (5) St. John's | C6: (5) St. John's | D6: (5) St. John's | E6: (5) St. John's | F6: (5) St. John's
A7: (12) N. Iowa
A8: (4) Kansas | B8: (4) Kansas
A9: (13) Cal Baptist
A10: (6) Louisville | B10: (6) Louisville
A11: (11) South Florida
A12: (3) Michigan St | B12: (3) Michigan St | C12: (3) Michigan St | D12: (3) Michigan St
A13: (14) N. Dakota St
A14: (7) UCLA
A15: (10) UCF | B15: (10) UCF
A16: (2) UConn | B16: (2) UConn | C16: (2) UConn
A17: (15) Furman
A18: (1) Florida | B18: (1) Florida | C18: (1) Florida | D18: (1) Florida
A19: **(16) PVAM/LEH
A20: (8) Clemson
A21: (9) Iowa | B21: (9) Iowa
A22: (5) Vanderbilt | B22: (5) Vanderbilt | C22: (5) Vanderbilt
A23: (12) McNeese
A24: (4) Nebraska
A25: (13) Troy | B25: (13) Troy
A26: (6) N. Carolina | B26: (6) N. Carolina
A27: (11) VCU
A28: (3) Illinois | B28: (3) Illinois | C28: (3) Illinois
A29: (14) Penn
A30: (7) Saint Mary's | B30: (7) Saint Mary's
A31: (10) Texas A&M
A32: (2) Houston | B32: (2) Houston | C32: (2) Houston | D32: (2) Houston | E32: (2) Houston
A33: (15) Idaho
A34: (1) Arizona | B34: (1) Arizona | C34: (1) Arizona | D34: (1) Arizona | E34: (1) Arizona | F34: (1) Arizona | G34: (1) Arizona
A35: (16) LIU
A36: (8) Villanova | B36: (8) Villanova
A37: (9) Utah St
A38: (5) Wisconsin
A39: (12) High Point | B39: (12) High Point
A40: (4) Arkansas | B40: (4) Arkansas | C40: (4) Arkansas
...

Sheet Roman
A1: Round of 64 | B1: Round of 32 | C1: Sweet 16 | D1: Elite 8 | E1: Final 4 | F1: Championship | G1: Winner
A2: (1) Duke | B2: (1) Duke | C2: (1) Duke | D2: (1) Duke | E2: (1) Duke | F2: (1) Duke
A3: (16) Siena
A4: (8) Ohio St
A5: (9) TCU | B5: (9) TCU
A6: (5) St. John's | B6: (5) St. John's | C6: (5) St. John's
A7: (12) N. Iowa
A8: (4) Kansas | B8: (4) Kansas
A9: (13) Cal Baptist
A10: (6) Louisville | B10: (6) Louisville
A11: (11) South Florida
A12: (3) Michigan St | B12: (3) Michigan St | C12: (3) Michigan St | D12: (3) Michigan St
A13: (14) N. Dakota St
A14: (7) UCLA
A15: (10) UCF | B15: (10) UCF
A16: (2) UConn | B16: (2) UConn | C16: (2) UConn
A17: (15) Furman
A18: (1) Florida | B18: (1) Florida | C18: (1) Florida | D18: (1) Florida
A19: **(16) PVAM/LEH
A20: (8) Clemson | B20: (8) Clemson
A21: (9) Iowa
A22: (5) Vanderbilt | B22: (5) Vanderbilt | C22: (5) Vanderbilt
A23: (12) McNeese
A24: (4) Nebraska | B24: (4) Nebraska
A25: (13) Troy
A26: (6) N. Carolina
A27: (11) VCU | B27: (11) VCU
A28: (3) Illinois | B28: (3) Illinois | C28: (3) Illinois
A29: (14) Penn
A30: (7) Saint Mary's
A31: (10) Texas A&M | B31: (10) Texas A&M
A32: (2) Houston | B32: (2) Houston | C32: (2) Houston | D32: (2) Houston | E32: (2) Houston
A33: (15) Idaho
A34: (1) Arizona | B34: (1) Arizona | C34: (1) Arizona | D34: (1) Arizona | E34: (1) Arizona | F34: (1) Arizona | G34: (1) Arizona
A35: (16) LIU
A36: (8) Villanova
A37: (9) Utah St | B37: (9) Utah St
A38: (5) Wisconsin | B38: (5) Wisconsin | C38: (5) Wisconsin
A39: (12) High Point
A40: (4) Arkansas | B40: (4) Arkansas
...

Sheet Eli
A1: Round of 64 | B1: Round of 32 | C1: Sweet 16 | D1: Elite 8 | E1: Final 4 | F1: Championship | G1: Winner
A2: (1) Duke | B2: (1) Duke | C2: (1) Duke | D2: (1) Duke | E2: (1) Duke | F2: (1) Duke | G2: (1) Duke
A3: (16) Siena
A4: (8) Ohio St
A5: (9) TCU | B5: (9) TCU
A6: (5) St. John's | B6: (5) St. John's
A7: (12) N. Iowa
A8: (4) Kansas | B8: (4) Kansas | C8: (4) Kansas
A9: (13) Cal Baptist
A10: (6) Louisville | B10: (6) Louisville
A11: (11) South Florida
A12: (3) Michigan St | B12: (3) Michigan St | C12: (3) Michigan St
A13: (14) N. Dakota St
A14: (7) UCLA | B14: (7) UCLA
A15: (10) UCF
A16: (2) UConn | B16: (2) UConn | C16: (2) UConn | D16: (2) UConn
A17: (15) Furman
A18: (1) Florida | B18: (1) Florida | C18: (1) Florida | D18: (1) Florida
A19: **(16) PVAM/LEH
A20: (8) Clemson
A21: (9) Iowa | B21: (9) Iowa
A22: (5) Vanderbilt
A23: (12) McNeese | B23: (12) McNeese
A24: (4) Nebraska | B24: (4) Nebraska | C24: (4) Nebraska
A25: (13) Troy
A26: (6) N. Carolina
A27: (11) VCU | B27: (11) VCU
A28: (3) Illinois | B28: (3) Illinois | C28: (3) Illinois
A29: (14) Penn
A30: (7) Saint Mary's
A31: (10) Texas A&M | B31: (10) Texas A&M
A32: (2) Houston | B32: (2) Houston | C32: (2) Houston | D32: (2) Houston | E32: (2) Houston
A33: (15) Idaho
A34: (1) Arizona | B34: (1) Arizona | C34: (1) Arizona | D34: (1) Arizona | E34: (1) Arizona
A35: (16) LIU
A36: (8) Villanova
A37: (9) Utah St | B37: (9) Utah St
A38: (5) Wisconsin | B38: (5) Wisconsin
A39: (12) High Point
A40: (4) Arkansas | B40: (4) Arkansas | C40: (4) Arkansas
...

Sheet Pete
A1: Round of 64 | B1: Round of 32 | C1: Sweet 16 | D1: Elite 8 | E1: Final 4 | F1: Championship | G1: Winner
A2: (1) Duke | B2: (1) Duke | C2: (1) Duke | D2: (1) Duke | E2: (1) Duke | F2: (1) Duke
A3: (16) Siena
A4: (8) Ohio St
A5: (9) TCU | B5: (9) TCU
A6: (5) St. John's | B6: (5) St. John's
A7: (12) N. Iowa
A8: (4) Kansas | B8: (4) Kansas | C8: (4) Kansas
A9: (13) Cal Baptist
A10: (6) Louisville | B10: (6) Louisville
A11: (11) South Florida
A12: (3) Michigan St | B12: (3) Michigan St | C12: (3) Michigan St
A13: (14) N. Dakota St
A14: (7) UCLA
A15: (10) UCF | B15: (10) UCF
A16: (2) UConn | B16: (2) UConn | C16: (2) UConn | D16: (2) UConn
A17: (15) Furman
A18: (1) Florida | B18: (1) Florida | C18: (1) Florida | D18: (1) Florida
A19: **(16) PVAM/LEH
A20: (8) Clemson
A21: (9) Iowa | B21: (9) Iowa
A22: (5) Vanderbilt | B22: (5) Vanderbilt
A23: (12) McNeese
A24: (4) Nebraska | B24: (4) Nebraska | C24: (4) Nebraska
A25: (13) Troy
A26: (6) N. Carolina | B26: (6) N. Carolina | C26: (6) N. Carolina | D26: (6) N. Carolina | E26: (6) N. Carolina
A27: (11) VCU
A28: (3) Illinois
A29: (14) Penn | B29: (14) Penn
A30: (7) Saint Mary's | B30: (7) Saint Mary's | C30: (7) Saint Mary's
A31: (10) Texas A&M
A32: (2) Houston | B32: (2) Houston
A33: (15) Idaho
A34: (1) Arizona | B34: (1) Arizona | C34: (1) Arizona | D34: (1) Arizona | E34: (1) Arizona | F34: (1) Arizona | G34: (1) Arizona
A35: (16) LIU
A36: (8) Villanova | B36: (8) Villanova
A37: (9) Utah St
A38: (5) Wisconsin | B38: (5) Wisconsin
A39: (12) High Point
A40: (4) Arkansas | B40: (4) Arkansas | C40: (4) Arkansas
...

Sheet Arden
A1: Round of 64 | B1: Round of 32 | C1: Sweet 16 | D1: Elite 8 | E1: Final 4 | F1: Championship | G1: Winner
A2: (1) Duke | B2: (1) Duke | C2: (1) Duke | D2: (1) Duke | E2: (1) Duke
A3: (16) Siena
A4: (8) Ohio St | B4: (8) Ohio St
A5: (9) TCU
A6: (5) St. John's | B6: (5) St. John's
A7: (12) N. Iowa
A8: (4) Kansas | B8: (4) Kansas | C8: (4) Kansas
A9: (13) Cal Baptist
A10: (6) Louisville | B10: (6) Louisville
A11: (11) South Florida
A12: (3) Michigan St | B12: (3) Michigan St | C12: (3) Michigan St
A13: (14) N. Dakota St
A14: (7) UCLA | B14: (7) UCLA
A15: (10) UCF
A16: (2) UConn | B16: (2) UConn | C16: (2) UConn | D16: (2) UConn
A17: (15) Furman
A18: (1) Florida | B18: (1) Florida | C18: (1) Florida | D18: (1) Florida | E18: (1) Florida | F18: (1) Florida | G18: (1) Florida
A19: **(16) PVAM/LEH
A20: (8) Clemson | B20: (8) Clemson
A21: (9) Iowa
A22: (5) Vanderbilt | B22: (5) Vanderbilt
A23: (12) McNeese
A24: (4) Nebraska | B24: (4) Nebraska | C24: (4) Nebraska
A25: (13) Troy
A26: (6) N. Carolina | B26: (6) N. Carolina
A27: (11) VCU
A28: (3) Illinois | B28: (3) Illinois | C28: (3) Illinois
A29: (14) Penn
A30: (7) Saint Mary's | B30: (7) Saint Mary's
A31: (10) Texas A&M
A32: (2) Houston | B32: (2) Houston | C32: (2) Houston | D32: (2) Houston
A33: (15) Idaho
A34: (1) Arizona | B34: (1) Arizona | C34: (1) Arizona | D34: (1) Arizona | E34: (1) Arizona
A35: (16) LIU
A36: (8) Villanova | B36: (8) Villanova
A37: (9) Utah St
A38: (5) Wisconsin | B38: (5) Wisconsin
A39: (12) High Point
A40: (4) Arkansas | B40: (4) Arkansas | C40: (4) Arkansas
...

Sheet Henny
A1: Round of 64 | B1: Round of 32 | C1: Sweet 16 | D1: Elite 8 | E1: Final 4 | F1: Championship | G1: Winner
A2: (1) Duke | B2: (1) Duke | C2: (1) Duke | D2: (1) Duke
A3: (16) Siena
A4: (8) Ohio St | B4: (8) Ohio St
A5: (9) TCU
A6: (5) St. John's | B6: (5) St. John's
A7: (12) N. Iowa
A8: (4) Kansas | B8: (4) Kansas | C8: (4) Kansas
A9: (13) Cal Baptist
A10: (6) Louisville | B10: (6) Louisville
A11: (11) South Florida
A12: (3) Michigan St | B12: (3) Michigan St | C12: (3) Michigan St | D12: (3) Michigan St | E12: (3) Michigan St | F12: (3) Michigan St | G12: (3) Michigan St
A13: (14) N. Dakota St
A14: (7) UCLA | B14: (7) UCLA
A15: (10) UCF
A16: (2) UConn | B16: (2) UConn | C16: (2) UConn
A17: (15) Furman
A18: (1) Florida | B18: (1) Florida | C18: (1) Florida | D18: (1) Florida | E18: (1) Florida
A19: **(16) PVAM/LEH
A20: (8) Clemson | B20: (8) Clemson
A21: (9) Iowa
A22: (5) Vanderbilt | B22: (5) Vanderbilt
A23: (12) McNeese
A24: (4) Nebraska | B24: (4) Nebraska | C24: (4) Nebraska
A25: (13) Troy
A26: (6) N. Carolina | B26: (6) N. Carolina | C26: (6) N. Carolina
A27: (11) VCU
A28: (3) Illinois | B28: (3) Illinois
A29: (14) Penn
A30: (7) Saint Mary's | B30: (7) Saint Mary's
A31: (10) Texas A&M
A32: (2) Houston | B32: (2) Houston | C32: (2) Houston | D32: (2) Houston
A33: (15) Idaho
A34: (1) Arizona | B34: (1) Arizona | C34: (1) Arizona | D34: (1) Arizona | E34: (1) Arizona | F34: (1) Arizona
A35: (16) LIU
A36: (8) Villanova | B36: (8) Villanova
A37: (9) Utah St
A38: (5) Wisconsin | B38: (5) Wisconsin
A39: (12) High Point
A40: (4) Arkansas | B40: (4) Arkansas | C40: (4) Arkansas
...

Sheet Sarah
A1: Round of 64 | B1: Round of 32 | C1: Sweet 16 | D1: Elite 8 | E1: Final 4 | F1: Championship | G1: Winner
A2: (1) Duke | B2: (1) Duke | C2: (1) Duke | D2: (1) Duke
A3: (16) Siena
A4: (8) Ohio St
A5: (9) TCU | B5: (9) TCU
A6: (5) St. John's | B6: (5) St. John's
A7: (12) N. Iowa
A8: (4) Kansas | B8: (4) Kansas | C8: (4) Kansas
A9: (13) Cal Baptist
A10: (6) Louisville | B10: (6) Louisville
A11: (11) South Florida
A12: (3) Michigan St | B12: (3) Michigan St | C12: (3) Michigan St | D12: (3) Michigan St | E12: (3) Michigan St
A13: (14) N. Dakota St
A14: (7) UCLA
A15: (10) UCF | B15: (10) UCF
A16: (2) UConn | B16: (2) UConn | C16: (2) UConn
A17: (15) Furman
A18: (1) Florida | B18: (1) Florida | C18: (1) Florida | D18: (1) Florida | E18: (1) Florida | F18: (1) Florida | G18: (1) Florida
A19: **(16) PVAM/LEH
A20: (8) Clemson
A21: (9) Iowa | B21: (9) Iowa
A22: (5) Vanderbilt | B22: (5) Vanderbilt
A23: (12) McNeese
A24: (4) Nebraska | B24: (4) Nebraska | C24: (4) Nebraska
A25: (13) Troy
A26: (6) N. Carolina | B26: (6) N. Carolina
A27: (11) VCU
A28: (3) Illinois | B28: (3) Illinois | C28: (3) Illinois
A29: (14) Penn
A30: (7) Saint Mary's
A31: (10) Texas A&M | B31: (10) Texas A&M
A32: (2) Houston | B32: (2) Houston | C32: (2) Houston | D32: (2) Houston
A33: (15) Idaho
A34: (1) Arizona | B34: (1) Arizona | C34: (1) Arizona | D34: (1) Arizona | E34: (1) Arizona
A35: (16) LIU
A36: (8) Villanova | B36: (8) Villanova
A37: (9) Utah St
A38: (5) Wisconsin | B38: (5) Wisconsin | C38: (5) Wisconsin
A39: (12) High Point
A40: (4) Arkansas | B40: (4) Arkansas
...

Sheet Chalamet
A1: Round of 64 | B1: Round of 32 | C1: Sweet 16 | D1: Elite 8 | E1: Final 4 | F1: Championship | G1: Winner
A2: (1) Duke | B2: (1) Duke
A3: (16) Siena
A4: (8) Ohio St | B4: (8) Ohio St | C4: (8) Ohio St
A5: (9) TCU
A6: (5) St. John's | B6: (5) St. John's
A7: (12) N. Iowa
A8: (4) Kansas | B8: (4) Kansas | C8: (4) Kansas | D8: (4) Kansas | E8: (4) Kansas | F8: (4) Kansas | G8: (4) Kansas
A9: (13) Cal Baptist
A10: (6) Louisville | B10: (6) Louisville | C10: (6) Louisville | D10: (6) Louisville
A11: (11) South Florida
A12: (3) Michigan St | B12: (3) Michigan St
A13: (14) N. Dakota St
A14: (7) UCLA | B14: (7) UCLA | C14: (7) UCLA
A15: (10) UCF
A16: (2) UConn | B16: (2) UConn
A17: (15) Furman
A18: (1) Florida | B18: (1) Florida | C18: (1) Florida
A19: **(16) PVAM/LEH
A20: (8) Clemson | B20: (8) Clemson
A21: (9) Iowa
A22: (5) Vanderbilt | B22: (5) Vanderbilt
A23: (12) McNeese
A24: (4) Nebraska | B24: (4) Nebraska | C24: (4) Nebraska | D24: (4) Nebraska
A25: (13) Troy
A26: (6) N. Carolina | B26: (6) N. Carolina | C26: (6) N. Carolina | D26: (6) N. Carolina | E26: (6) N. Carolina
A27: (11) VCU
A28: (3) Illinois | B28: (3) Illinois
A29: (14) Penn
A30: (7) Saint Mary's | B30: (7) Saint Mary's | C30: (7) Saint Mary's
A31: (10) Texas A&M
A32: (2) Houston | B32: (2) Houston
A33: (15) Idaho
A34: (1) Arizona | B34: (1) Arizona
A35: (16) LIU
A36: (8) Villanova | B36: (8) Villanova | C36: (8) Villanova | D36: (8) Villanova
A37: (9) Utah St
A38: (5) Wisconsin | B38: (5) Wisconsin | C38: (5) Wisconsin
A39: (12) High Point
A40: (4) Arkansas | B40: (4) Arkansas
...

Sheet Cynthia
A1: Round of 64 | B1: Round of 32 | C1: Sweet 16 | D1: Elite 8 | E1: Final 4 | F1: Championship | G1: Winner
A2: (1) Duke | B2: (1) Duke | C2: (1) Duke
A3: (16) Siena
A4: (8) Ohio St
A5: (9) TCU | B5: (9) TCU
A6: (5) St. John's | B6: (5) St. John's
A7: (12) N. Iowa
A8: (4) Kansas | B8: (4) Kansas | C8: (4) Kansas | D8: (4) Kansas
A9: (13) Cal Baptist
A10: (6) Louisville | B10: (6) Louisville
A11: (11) South Florida
A12: (3) Michigan St | B12: (3) Michigan St | C12: (3) Michigan St
A13: (14) N. Dakota St
A14: (7) UCLA | B14: (7) UCLA
A15: (10) UCF
A16: (2) UConn | B16: (2) UConn | C16: (2) UConn | D16: (2) UConn | E16: (2) UConn | F16: (2) UConn
A17: (15) Furman
A18: (1) Florida | B18: (1) Florida | C18: (1) Florida
A19: **(16) PVAM/LEH
A20: (8) Clemson
A21: (9) Iowa | B21: (9) Iowa
A22: (5) Vanderbilt | B22: (5) Vanderbilt | C22: (5) Vanderbilt | D22: (5) Vanderbilt
A23: (12) McNeese
A24: (4) Nebraska | B24: (4) Nebraska
A25: (13) Troy
A26: (6) N. Carolina | B26: (6) N. Carolina
A27: (11) VCU
A28: (3) Illinois | B28: (3) Illinois | C28: (3) Illinois | D28: (3) Illinois | E28: (3) Illinois
A29: (14) Penn
A30: (7) Saint Mary's | B30: (7) Saint Mary's | C30: (7) Saint Mary's
A31: (10) Texas A&M
A32: (2) Houston | B32: (2) Houston
A33: (15) Idaho
A34: (1) Arizona | B34: (1) Arizona | C34: (1) Arizona | D34: (1) Arizona | E34: (1) Arizona | F34: (1) Arizona | G34: (1) Arizona
A35: (16) LIU
A36: (8) Villanova | B36: (8) Villanova
A37: (9) Utah St
A38: (5) Wisconsin | B38: (5) Wisconsin | C38: (5) Wisconsin
A39: (12) High Point
A40: (4) Arkansas | B40: (4) Arkansas
...

Sheet Tim
A1: Round of 64 | B1: Round of 32 | C1: Sweet 16 | D1: Elite 8 | E1: Final 4 | F1: Championship | G1: Winner
A2: (1) Duke | B2: (1) Duke | C2: (1) Duke | D2: (1) Duke | E2: (1) Duke | F2: (1) Duke
A3: (16) Siena
A4: (8) Ohio St
A5: (9) TCU | B5: (9) TCU
A6: (5) St. John's | B6: (5) St. John's
A7: (12) N. Iowa
A8: (4) Kansas | B8: (4) Kansas | C8: (4) Kansas
A9: (13) Cal Baptist
A10: (6) Louisville | B10: (6) Louisville
A11: (11) South Florida
A12: (3) Michigan St | B12: (3) Michigan St | C12: (3) Michigan St | D12: (3) Michigan St
A13: (14) N. Dakota St
A14: (7) UCLA
A15: (10) UCF | B15: (10) UCF
A16: (2) UConn | B16: (2) UConn | C16: (2) UConn
A17: (15) Furman
A18: (1) Florida | B18: (1) Florida | C18: (1) Florida
A19: **(16) PVAM/LEH
A20: (8) Clemson
A21: (9) Iowa | B21: (9) Iowa
A22: (5) Vanderbilt | B22: (5) Vanderbilt | C22: (5) Vanderbilt | D22: (5) Vanderbilt
A23: (12) McNeese
A24: (4) Nebraska | B24: (4) Nebraska
A25: (13) Troy
A26: (6) N. Carolina
A27: (11) VCU | B27: (11) VCU
A28: (3) Illinois | B28: (3) Illinois | C28: (3) Illinois | D28: (3) Illinois | E28: (3) Illinois
A29: (14) Penn
A30: (7) Saint Mary's
A31: (10) Texas A&M | B31: (10) Texas A&M | C31: (10) Texas A&M
A32: (2) Houston | B32: (2) Houston
A33: (15) Idaho
A34: (1) Arizona | B34: (1) Arizona | C34: (1) Arizona | D34: (1) Arizona | E34: (1) Arizona
A35: (16) LIU
A36: (8) Villanova | B36: (8) Villanova
A37: (9) Utah St
A38: (5) Wisconsin | B38: (5) Wisconsin
A39: (12) High Point
A40: (4) Arkansas | B40: (4) Arkansas | C40: (4) Arkansas
...

Sheet Emma
A1: Round of 64 | B1: Round of 32 | C1: Sweet 16 | D1: Elite 8 | E1: Final 4 | F1: Championship | G1: Winner
A2: (1) Duke | B2: (1) Duke | C2: (1) Duke | D2: (1) Duke | E2: (1) Duke
A3: (16) Siena
A4: (8) Ohio St
A5: (9) TCU | B5: (9) TCU
A6: (5) St. John's | B6: (5) St. John's | C6: (5) St. John's
A7: (12) N. Iowa
A8: (4) Kansas | B8: (4) Kansas
A9: (13) Cal Baptist
A10: (6) Louisville | B10: (6) Louisville | C10: (6) Louisville | D10: (6) Louisville
A11: (11) South Florida
A12: (3) Michigan St | B12: (3) Michigan St
A13: (14) N. Dakota St
A14: (7) UCLA
A15: (10) UCF | B15: (10) UCF
A16: (2) UConn | B16: (2) UConn | C16: (2) UConn
A17: (15) Furman
A18: (1) Florida | B18: (1) Florida | C18: (1) Florida
A19: **(16) PVAM/LEH
A20: (8) Clemson
A21: (9) Iowa | B21: (9) Iowa
A22: (5) Vanderbilt | B22: (5) Vanderbilt
A23: (12) McNeese
A24: (4) Nebraska | B24: (4) Nebraska | C24: (4) Nebraska | D24: (4) Nebraska
A25: (13) Troy
A26: (6) N. Carolina | B26: (6) N. Carolina | C26: (6) N. Carolina
A27: (11) VCU
A28: (3) Illinois | B28: (3) Illinois
A29: (14) Penn
A30: (7) Saint Mary's | B30: (7) Saint Mary's
A31: (10) Texas A&M
A32: (2) Houston | B32: (2) Houston | C32: (2) Houston | D32: (2) Houston | E32: (2) Houston | F32: (2) Houston | G32: (2) Houston
A33: (15) Idaho
A34: (1) Arizona | B34: (1) Arizona | C34: (1) Arizona | D34: (1) Arizona | E34: (1) Arizona | F34: (1) Arizona
A35: (16) LIU
A36: (8) Villanova
A37: (9) Utah St | B37: (9) Utah St
A38: (5) Wisconsin
A39: (12) High Point | B39: (12) High Point | C39: (12) High Point
A40: (4) Arkansas | B40: (4) Arkansas
...

Sheet Mary
A1: Round of 64 | B1: Round of 32 | C1: Sweet 16 | D1: Elite 8 | E1: Final 4 | F1: Championship | G1: Winner
A2: (1) Duke | B2: (1) Duke | C2: (1) Duke | D2: (1) Duke | E2: (1) Duke
A3: (16) Siena
A4: (8) Ohio St
A5: (9) TCU | B5: (9) TCU
A6: (5) St. John's | B6: (5) St. John's
A7: (12) N. Iowa
A8: (4) Kansas | B8: (4) Kansas | C8: (4) Kansas
A9: (13) Cal Baptist
A10: (6) Louisville | B10: (6) Louisville
A11: (11) South Florida
A12: (3) Michigan St | B12: (3) Michigan St | C12: (3) Michigan St
A13: (14) N. Dakota St
A14: (7) UCLA | B14: (7) UCLA
A15: (10) UCF
A16: (2) UConn | B16: (2) UConn | C16: (2) UConn | D16: (2) UConn
A17: (15) Furman
A18: (1) Florida | B18: (1) Florida | C18: (1) Florida | D18: (1) Florida
A19: **(16) PVAM/LEH
A20: (8) Clemson | B20: (8) Clemson
A21: (9) Iowa
A22: (5) Vanderbilt | B22: (5) Vanderbilt
A23: (12) McNeese
A24: (4) Nebraska | B24: (4) Nebraska | C24: (4) Nebraska
A25: (13) Troy
A26: (6) N. Carolina | B26: (6) N. Carolina | C26: (6) N. Carolina
A27: (11) VCU
A28: (3) Illinois | B28: (3) Illinois
A29: (14) Penn
A30: (7) Saint Mary's | B30: (7) Saint Mary's
A31: (10) Texas A&M
A32: (2) Houston | B32: (2) Houston | C32: (2) Houston | D32: (2) Houston | E32: (2) Houston | F32: (2) Houston | G32: (2) Houston
A33: (15) Idaho
A34: (1) Arizona | B34: (1) Arizona | C34: (1) Arizona | D34: (1) Arizona | E34: (1) Arizona | F34: (1) Arizona
A35: (16) LIU
A36: (8) Villanova | B36: (8) Villanova
A37: (9) Utah St
A38: (5) Wisconsin | B38: (5) Wisconsin | C38: (5) Wisconsin
A39: (12) High Point
A40: (4) Arkansas | B40: (4) Arkansas
...

Sheet Chad
A1: Round of 64 | B1: Round of 32 | C1: Sweet 16 | D1: Elite 8 | E1: Final 4 | F1: Championship | G1: Winner
A2: (1) Duke | B2: (1) Duke | C2: (1) Duke | D2: (1) Duke
A3: (16) Siena
A4: (8) Ohio St | B4: (8) Ohio St
A5: (9) TCU
A6: (5) St. John's | B6: (5) St. John's
A7: (12) N. Iowa
A8: (4) Kansas | B8: (4) Kansas | C8: (4) Kansas
A9: (13) Cal Baptist
A10: (6) Louisville | B10: (6) Louisville
A11: (11) South Florida
A12: (3) Michigan St | B12: (3) Michigan St | C12: (3) Michigan St | D12: (3) Michigan St | E12: (3) Michigan St
A13: (14) N. Dakota St
A14: (7) UCLA | B14: (7) UCLA | C14: (7) UCLA
A15: (10) UCF
A16: (2) UConn | B16: (2) UConn
A17: (15) Furman
A18: (1) Florida | B18: (1) Florida | C18: (1) Florida | D18: (1) Florida
A19: **(16) PVAM/LEH
A20: (8) Clemson
A21: (9) Iowa | B21: (9) Iowa
A22: (5) Vanderbilt | B22: (5) Vanderbilt
A23: (12) McNeese
A24: (4) Nebraska | B24: (4) Nebraska | C24: (4) Nebraska
A25: (13) Troy
A26: (6) N. Carolina | B26: (6) N. Carolina
A27: (11) VCU
A28: (3) Illinois | B28: (3) Illinois | C28: (3) Illinois
A29: (14) Penn
A30: (7) Saint Mary's | B30: (7) Saint Mary's
A31: (10) Texas A&M
A32: (2) Houston | B32: (2) Houston | C32: (2) Houston | D32: (2) Houston | E32: (2) Houston | F32: (2) Houston
A33: (15) Idaho
A34: (1) Arizona | B34: (1) Arizona | C34: (1) Arizona | D34: (1) Arizona | E34: (1) Arizona
A35: (16) LIU
A36: (8) Villanova
A37: (9) Utah St | B37: (9) Utah St
A38: (5) Wisconsin | B38: (5) Wisconsin
A39: (12) High Point
A40: (4) Arkansas | B40: (4) Arkansas | C40: (4) Arkansas
...

Sheet Truett
A1: Round of 64 | B1: Round of 32 | C1: Sweet 16 | D1: Elite 8 | E1: Final 4 | F1: Championship | G1: Winner
A2: (1) Duke | B2: (1) Duke | C2: (1) Duke | D2: (1) Duke | E2: (1) Duke | F2: (1) Duke
A3: (16) Siena
A4: (8) Ohio St
A5: (9) TCU | B5: (9) TCU
A6: (5) St. John's | B6: (5) St. John's
A7: (12) N. Iowa
A8: (4) Kansas | B8: (4) Kansas | C8: (4) Kansas
A9: (13) Cal Baptist
A10: (6) Louisville | B10: (6) Louisville
A11: (11) South Florida
A12: (3) Michigan St | B12: (3) Michigan St | C12: (3) Michigan St
A13: (14) N. Dakota St
A14: (7) UCLA | B14: (7) UCLA
A15: (10) UCF
A16: (2) UConn | B16: (2) UConn | C16: (2) UConn | D16: (2) UConn
A17: (15) Furman
A18: (1) Florida | B18: (1) Florida | C18: (1) Florida | D18: (1) Florida | E18: (1) Florida
A19: **(16) PVAM/LEH
A20: (8) Clemson
A21: (9) Iowa | B21: (9) Iowa
A22: (5) Vanderbilt | B22: (5) Vanderbilt
A23: (12) McNeese
A24: (4) Nebraska | B24: (4) Nebraska | C24: (4) Nebraska
A25: (13) Troy
A26: (6) N. Carolina | B26: (6) N. Carolina
A27: (11) VCU
A28: (3) Illinois | B28: (3) Illinois | C28: (3) Illinois
A29: (14) Penn
A30: (7) Saint Mary's | B30: (7) Saint Mary's
A31: (10) Texas A&M
A32: (2) Houston | B32: (2) Houston | C32: (2) Houston | D32: (2) Houston
A33: (15) Idaho
A34: (1) Arizona | B34: (1) Arizona | C34: (1) Arizona | D34: (1) Arizona | E34: (1) Arizona
A35: (16) LIU
A36: (8) Villanova
A37: (9) Utah St | B37: (9) Utah St
A38: (5) Wisconsin | B38: (5) Wisconsin
A39: (12) High Point
A40: (4) Arkansas | B40: (4) Arkansas | C40: (4) Arkansas
...

Sheet Lucia
A1: Round of 64 | B1: Round of 32 | C1: Sweet 16 | D1: Elite 8 | E1: Final 4 | F1: Championship | G1: Winner
A2: (1) Duke | B2: (1) Duke | C2: (1) Duke
A3: (16) Siena
A4: (8) Ohio St
A5: (9) TCU | B5: (9) TCU
A6: (5) St. John's | B6: (5) St. John's | C6: (5) St. John's | D6: (5) St. John's
A7: (12) N. Iowa
A8: (4) Kansas | B8: (4) Kansas
A9: (13) Cal Baptist
A10: (6) Louisville
A11: (11) South Florida | B11: (11) South Florida
A12: (3) Michigan St | B12: (3) Michigan St | C12: (3) Michigan St | D12: (3) Michigan St | E12: (3) Michigan St | F12: (3) Michigan St | G12: (3) Michigan St
A13: (14) N. Dakota St
A14: (7) UCLA
A15: (10) UCF | B15: (10) UCF
A16: (2) UConn | B16: (2) UConn | C16: (2) UConn
A17: (15) Furman
A18: (1) Florida | B18: (1) Florida | C18: (1) Florida | D18: (1) Florida | E18: (1) Florida
A19: **(16) PVAM/LEH
A20: (8) Clemson
A21: (9) Iowa | B21: (9) Iowa
A22: (5) Vanderbilt | B22: (5) Vanderbilt | C22: (5) Vanderbilt
A23: (12) McNeese
A24: (4) Nebraska | B24: (4) Nebraska
A25: (13) Troy
A26: (6) N. Carolina | B26: (6) N. Carolina | C26: (6) N. Carolina
A27: (11) VCU
A28: (3) Illinois | B28: (3) Illinois
A29: (14) Penn
A30: (7) Saint Mary's | B30: (7) Saint Mary's
A31: (10) Texas A&M
A32: (2) Houston | B32: (2) Houston | C32: (2) Houston | D32: (2) Houston
A33: (15) Idaho
A34: (1) Arizona | B34: (1) Arizona | C34: (1) Arizona | D34: (1) Arizona | E34: (1) Arizona
A35: (16) LIU
A36: (8) Villanova
A37: (9) Utah St | B37: (9) Utah St
A38: (5) Wisconsin
A39: (12) High Point | B39: (12) High Point
A40: (4) Arkansas | B40: (4) Arkansas | C40: (4) Arkansas
...

Sheet Sabine
A1: Round of 64 | B1: Round of 32 | C1: Sweet 16 | D1: Elite 8 | E1: Final 4 | F1: Championship | G1: Winner
A2: (1) Duke | B2: (1) Duke
A3: (16) Siena
A4: (8) Ohio St | B4: (8) Ohio St | C4: (8) Ohio St | D4: (8) Ohio St | E4: (8) Ohio St
A5: (9) TCU
A6: (5) St. John's
A7: (12) N. Iowa | B7: (12) N. Iowa
A8: (4) Kansas | B8: (4) Kansas | C8: (4) Kansas
A9: (13) Cal Baptist
A10: (6) Louisville | B10: (6) Louisville
A11: (11) South Florida
A12: (3) Michigan St | B12: (3) Michigan St | C12: (3) Michigan St | D12: (3) Michigan St
A13: (14) N. Dakota St
A14: (7) UCLA | B14: (7) UCLA | C14: (7) UCLA
A15: (10) UCF
A16: (2) UConn
A17: (15) Furman | B17: (15) Furman
A18: (1) Florida | B18: (1) Florida
A19: **(16) PVAM/LEH
A20: (8) Clemson
A21: (9) Iowa | B21: (9) Iowa | C21: (9) Iowa | D21: (9) Iowa
A22: (5) Vanderbilt
A23: (12) McNeese | B23: (12) McNeese
A24: (4) Nebraska | B24: (4) Nebraska | C24: (4) Nebraska
A25: (13) Troy
A26: (6) N. Carolina | B26: (6) N. Carolina
A27: (11) VCU
A28: (3) Illinois | B28: (3) Illinois | C28: (3) Illinois
A29: (14) Penn
A30: (7) Saint Mary's
A31: (10) Texas A&M | B31: (10) Texas A&M | C31: (10) Texas A&M | D31: (10) Texas A&M | E31: (10) Texas A&M | F31: (10) Texas A&M
A32: (2) Houston | B32: (2) Houston
A33: (15) Idaho
A34: (1) Arizona | B34: (1) Arizona | C34: (1) Arizona
A35: (16) LIU
A36: (8) Villanova
A37: (9) Utah St | B37: (9) Utah St
A38: (5) Wisconsin | B38: (5) Wisconsin
A39: (12) High Point
A40: (4) Arkansas | B40: (4) Arkansas | C40: (4) Arkansas | D40: (4) Arkansas | E40: (4) Arkansas
...

Sheet Pia
A1: Round of 64 | B1: Round of 32 | C1: Sweet 16 | D1: Elite 8 | E1: Final 4 | F1: Championship | G1: Winner
A2: (1) Duke
A3: (16) Siena | B3: (16) Siena | C3: (16) Siena | D3: (16) Siena | E3: (16) Siena | F3: (16) Siena | G3: (16) Siena
A4: (8) Ohio St | B4: (8) Ohio St
A5: (9) TCU
A6: (5) St. John's
A7: (12) N. Iowa | B7: (12) N. Iowa
A8: (4) Kansas | B8: (4) Kansas | C8: (4) Kansas
A9: (13) Cal Baptist
A10: (6) Louisville
A11: (11) South Florida | B11: (11) South Florida
A12: (3) Michigan St | B12: (3) Michigan St | C12: (3) Michigan St | D12: (3) Michigan St
A13: (14) N. Dakota St
A14: (7) UCLA
A15: (10) UCF | B15: (10) UCF | C15: (10) UCF
A16: (2) UConn | B16: (2) UConn
A17: (15) Furman
A18: (1) Florida | B18: (1) Florida
A19: **(16) PVAM/LEH
A20: (8) Clemson
A21: (9) Iowa | B21: (9) Iowa | C21: (9) Iowa
A22: (5) Vanderbilt | B22: (5) Vanderbilt
A23: (12) McNeese
A24: (4) Nebraska | B24: (4) Nebraska | C24: (4) Nebraska | D24: (4) Nebraska | E24: (4) Nebraska
A25: (13) Troy
A26: (6) N. Carolina | B26: (6) N. Carolina | C26: (6) N. Carolina
A27: (11) VCU
A28: (3) Illinois | B28: (3) Illinois
A29: (14) Penn
A30: (7) Saint Mary's | B30: (7) Saint Mary's
A31: (10) Texas A&M
A32: (2) Houston
A33: (15) Idaho | B33: (15) Idaho | C33: (15) Idaho | D33: (15) Idaho
A34: (1) Arizona | B34: (1) Arizona
A35: (16) LIU
A36: (8) Villanova
A37: (9) Utah St | B37: (9) Utah St | C37: (9) Utah St
A38: (5) Wisconsin | B38: (5) Wisconsin
A39: (12) High Point
A40: (4) Arkansas
...

Sheet August
A1: Round of 64 | B1: Round of 32 | C1: Sweet 16 | D1: Elite 8 | E1: Final 4 | F1: Championship | G1: Winner
A2: (1) Duke | B2: (1) Duke | C2: (1) Duke | D2: (1) Duke | E2: (1) Duke
A3: (16) Siena
A4: (8) Ohio St
A5: (9) TCU | B5: (9) TCU
A6: (5) St. John's | B6: (5) St. John's
A7: (12) N. Iowa
A8: (4) Kansas | B8: (4) Kansas | C8: (4) Kansas
A9: (13) Cal Baptist
A10: (6) Louisville
A11: (11) South Florida | B11: (11) South Florida
A12: (3) Michigan St | B12: (3) Michigan St | C12: (3) Michigan St | D12: (3) Michigan St
A13: (14) N. Dakota St
A14: (7) UCLA | B14: (7) UCLA | C14: (7) UCLA
A15: (10) UCF
A16: (2) UConn | B16: (2) UConn
A17: (15) Furman
A18: (1) Florida | B18: (1) Florida | C18: (1) Florida | D18: (1) Florida
A19: **(16) PVAM/LEH
A20: (8) Clemson
A21: (9) Iowa | B21: (9) Iowa
A22: (5) Vanderbilt | B22: (5) Vanderbilt | C22: (5) Vanderbilt
A23: (12) McNeese
A24: (4) Nebraska | B24: (4) Nebraska
A25: (13) Troy
A26: (6) N. Carolina
A27: (11) VCU | B27: (11) VCU
A28: (3) Illinois | B28: (3) Illinois | C28: (3) Illinois
A29: (14) Penn
A30: (7) Saint Mary's
A31: (10) Texas A&M | B31: (10) Texas A&M
A32: (2) Houston | B32: (2) Houston | C32: (2) Houston | D32: (2) Houston | E32: (2) Houston | F32: (2) Houston | G32: (2) Houston
A33: (15) Idaho
A34: (1) Arizona | B34: (1) Arizona
A35: (16) LIU
A36: (8) Villanova
A37: (9) Utah St | B37: (9) Utah St | C37: (9) Utah St
A38: (5) Wisconsin | B38: (5) Wisconsin | C38: (5) Wisconsin | D38: (5) Wisconsin | E38: (5) Wisconsin | F38: (5) Wisconsin
A39: (12) High Point
A40: (4) Arkansas | B40: (4) Arkansas
...

Sheet Penny
A1: Round of 64 | B1: Round of 32 | C1: Sweet 16 | D1: Elite 8 | E1: Final 4 | F1: Championship | G1: Winner
A2: (1) Duke | B2: (1) Duke | C2: (1) Duke | D2: (1) Duke | E2: (1) Duke | F2: (1) Duke | G2: (1) Duke
A3: (16) Siena
A4: (8) Ohio St | B4: (8) Ohio St
A5: (9) TCU
A6: (5) St. John's | B6: (5) St. John's
A7: (12) N. Iowa
A8: (4) Kansas | B8: (4) Kansas | C8: (4) Kansas
A9: (13) Cal Baptist
A10: (6) Louisville | B10: (6) Louisville
A11: (11) South Florida
A12: (3) Michigan St | B12: (3) Michigan St | C12: (3) Michigan St
A13: (14) N. Dakota St
A14: (7) UCLA | B14: (7) UCLA
A15: (10) UCF
A16: (2) UConn | B16: (2) UConn | C16: (2) UConn | D16: (2) UConn
A17: (15) Furman
A18: (1) Florida | B18: (1) Florida | C18: (1) Florida | D18: (1) Florida | E18: (1) Florida
A19: **(16) PVAM/LEH
A20: (8) Clemson | B20: (8) Clemson
A21: (9) Iowa
A22: (5) Vanderbilt | B22: (5) Vanderbilt
A23: (12) McNeese
A24: (4) Nebraska | B24: (4) Nebraska | C24: (4) Nebraska
A25: (13) Troy
A26: (6) N. Carolina | B26: (6) N. Carolina
A27: (11) VCU
A28: (3) Illinois | B28: (3) Illinois | C28: (3) Illinois
A29: (14) Penn
A30: (7) Saint Mary's | B30: (7) Saint Mary's
A31: (10) Texas A&M
A32: (2) Houston | B32: (2) Houston | C32: (2) Houston | D32: (2) Houston
A33: (15) Idaho
A34: (1) Arizona | B34: (1) Arizona | C34: (1) Arizona | D34: (1) Arizona | E34: (1) Arizona | F34: (1) Arizona
A35: (16) LIU
A36: (8) Villanova | B36: (8) Villanova
A37: (9) Utah St
A38: (5) Wisconsin | B38: (5) Wisconsin
A39: (12) High Point
A40: (4) Arkansas | B40: (4) Arkansas | C40: (4) Arkansas
...

Sheet Don
A1: Round of 64 | B1: Round of 32 | C1: Sweet 16 | D1: Elite 8 | E1: Final 4 | F1: Championship | G1: Winner
A2: (1) Duke | B2: (1) Duke | C2: (1) Duke | D2: (1) Duke | E2: (1) Duke | F2: (1) Duke
A3: (16) Siena
A4: (8) Ohio St | B4: (8) Ohio St
A5: (9) TCU
A6: (5) St. John's | B6: (5) St. John's | C6: (5) St. John's
A7: (12) N. Iowa
A8: (4) Kansas | B8: (4) Kansas
A9: (13) Cal Baptist
A10: (6) Louisville
A11: (11) South Florida | B11: (11) South Florida
A12: (3) Michigan St | B12: (3) Michigan St | C12: (3) Michigan St
A13: (14) N. Dakota St
A14: (7) UCLA
A15: (10) UCF | B15: (10) UCF
A16: (2) UConn | B16: (2) UConn | C16: (2) UConn | D16: (2) UConn
A17: (15) Furman
A18: (1) Florida | B18: (1) Florida | C18: (1) Florida | D18: (1) Florida
A19: **(16) PVAM/LEH
A20: (8) Clemson
A21: (9) Iowa | B21: (9) Iowa
A22: (5) Vanderbilt | B22: (5) Vanderbilt | C22: (5) Vanderbilt
A23: (12) McNeese
A24: (4) Nebraska | B24: (4) Nebraska
A25: (13) Troy
A26: (6) N. Carolina
A27: (11) VCU | B27: (11) VCU
A28: (3) Illinois | B28: (3) Illinois | C28: (3) Illinois
A29: (14) Penn
A30: (7) Saint Mary's | B30: (7) Saint Mary's
A31: (10) Texas A&M
A32: (2) Houston | B32: (2) Houston | C32: (2) Houston | D32: (2) Houston | E32: (2) Houston
A33: (15) Idaho
A34: (1) Arizona | B34: (1) Arizona | C34: (1) Arizona | D34: (1) Arizona | E34: (1) Arizona
A35: (16) LIU
A36: (8) Villanova
A37: (9) Utah St | B37: (9) Utah St
A38: (5) Wisconsin | B38: (5) Wisconsin
A39: (12) High Point
A40: (4) Arkansas | B40: (4) Arkansas | C40: (4) Arkansas
...

Sheet Indie
A1: Round of 64 | B1: Round of 32 | C1: Sweet 16 | D1: Elite 8 | E1: Final 4 | F1: Championship | G1: Winner
A2: (1) Duke | B2: (1) Duke | C2: (1) Duke | D2: (1) Duke | E2: (1) Duke | F2: (1) Duke | G2: (1) Duke
A3: (16) Siena
A4: (8) Ohio St | B4: (8) Ohio St
A5: (9) TCU
A6: (5) St. John's | B6: (5) St. John's | C6: (5) St. John's
A7: (12) N. Iowa
A8: (4) Kansas | B8: (4) Kansas
A9: (13) Cal Baptist
A10: (6) Louisville
A11: (11) South Florida | B11: (11) South Florida
A12: (3) Michigan St | B12: (3) Michigan St | C12: (3) Michigan St | D12: (3) Michigan St
A13: (14) N. Dakota St
A14: (7) UCLA | B14: (7) UCLA | C14: (7) UCLA
A15: (10) UCF
A16: (2) UConn | B16: (2) UConn
A17: (15) Furman
A18: (1) Florida | B18: (1) Florida | C18: (1) Florida | D18: (1) Florida
A19: **(16) PVAM/LEH
A20: (8) Clemson
A21: (9) Iowa | B21: (9) Iowa
A22: (5) Vanderbilt | B22: (5) Vanderbilt | C22: (5) Vanderbilt
A23: (12) McNeese
A24: (4) Nebraska | B24: (4) Nebraska
A25: (13) Troy
A26: (6) N. Carolina
A27: (11) VCU | B27: (11) VCU
A28: (3) Illinois | B28: (3) Illinois | C28: (3) Illinois | D28: (3) Illinois | E28: (3) Illinois
A29: (14) Penn
A30: (7) Saint Mary's | B30: (7) Saint Mary's
A31: (10) Texas A&M
A32: (2) Houston | B32: (2) Houston | C32: (2) Houston
A33: (15) Idaho
A34: (1) Arizona | B34: (1) Arizona | C34: (1) Arizona | D34: (1) Arizona | E34: (1) Arizona
A35: (16) LIU
A36: (8) Villanova | B36: (8) Villanova
A37: (9) Utah St
A38: (5) Wisconsin | B38: (5) Wisconsin | C38: (5) Wisconsin
A39: (12) High Point
A40: (4) Arkansas | B40: (4) Arkansas
...

Sheet Winter
A1: Round of 64 | B1: Round of 32 | C1: Sweet 16 | D1: Elite 8 | E1: Final 4 | F1: Championship | G1: Winner
A2: (1) Duke | B2: (1) Duke | C2: (1) Duke
A3: (16) Siena
A4: (8) Ohio St | B4: (8) Ohio St
A5: (9) TCU
A6: (5) St. John's | B6: (5) St. John's
A7: (12) N. Iowa
A8: (4) Kansas | B8: (4) Kansas | C8: (4) Kansas | D8: (4) Kansas
A9: (13) Cal Baptist
A10: (6) Louisville | B10: (6) Louisville | C10: (6) Louisville | D10: (6) Louisville | E10: (6) Louisville
A11: (11) South Florida
A12: (3) Michigan St | B12: (3) Michigan St
A13: (14) N. Dakota St
A14: (7) UCLA | B14: (7) UCLA
A15: (10) UCF
A16: (2) UConn | B16: (2) UConn | C16: (2) UConn
A17: (15) Furman
A18: (1) Florida | B18: (1) Florida | C18: (1) Florida
A19: **(16) PVAM/LEH
A20: (8) Clemson | B20: (8) Clemson
A21: (9) Iowa
A22: (5) Vanderbilt | B22: (5) Vanderbilt | C22: (5) Vanderbilt | D22: (5) Vanderbilt | E22: (5) Vanderbilt | F22: (5) Vanderbilt | G22: (5) Vanderbilt
A23: (12) McNeese
A24: (4) Nebraska | B24: (4) Nebraska
A25: (13) Troy
A26: (6) N. Carolina | B26: (6) N. Carolina | C26: (6) N. Carolina | D26: (6) N. Carolina
A27: (11) VCU
A28: (3) Illinois | B28: (3) Illinois
A29: (14) Penn
A30: (7) Saint Mary's | B30: (7) Saint Mary's
A31: (10) Texas A&M
A32: (2) Houston | B32: (2) Houston | C32: (2) Houston
A33: (15) Idaho
A34: (1) Arizona | B34: (1) Arizona | C34: (1) Arizona
A35: (16) LIU
A36: (8) Villanova | B36: (8) Villanova
A37: (9) Utah St
A38: (5) Wisconsin | B38: (5) Wisconsin
A39: (12) High Point
A40: (4) Arkansas | B40: (4) Arkansas | C40: (4) Arkansas | D40: (4) Arkansas | E40: (4) Arkansas
...

Sheet Contestant
A1: Round of 64 | B1: Round of 32 | C1: Sweet 16 | D1: Elite 8 | E1: Final 4 | F1: Championship | G1: Winner
A2: (1) Auburn
A3: (16) Alabama St
A4: (8) Louisville
A5: (9) Creighton
A6: (5) Michigan
A7: (12) UC San Diego
A8: (4) Texas A&M
A9: (13) Yale
A10: (6) Ole Miss
A11: (11) North Carolina
A12: (3) Iowa State
A13: (14) Lipscomb
... A65: (15) Wofford
